Workbook

Sheet 概要
A1: クリーンルーム事実票：取り込み結果の概要
A2: 作成：2026-10-31（hm-cmed/cleanroom-facts の data/ から作成。件数は数式で数えています）
A4: ■ 全体
A5: カード（廃止を含む） | B5: =COUNTA(カード一覧!A2:A3170) -> 3169
A6: 有効なカード | B6: =COUNTIF(カード一覧!N2:N3170,"<>retired") -> 3136
A7: 廃止したカード | B7: =COUNTIF(カード一覧!N2:N3170,"retired") -> 33
A8: 専門医の監修済み（verified_expert） | B8: =COUNTIF(カード一覧!N2:N3170,"verified_expert") -> 0
A9: 出典 | B9: =COUNTA(出典一覧!A2:A1840) -> 1839
A10: 出題基準の項目 | B10: =COUNTA(出題基準の網羅!D2:D1483) -> 1482
A11: カードのある項目 | B11: =COUNTIF(出題基準の網羅!H2:H1483,"あり") -> 1174
A12: 項目の網羅率 | B12: =B11/B10 -> 0.79217274
A14: ■ 章ごとの出題基準の網羅
A15: 章 | B15: 章の名前 | C15: 項目 | D15: レベル a | E15: カードのある項目 | F15: 網羅率 | G15: レベル a でカードのない項目
A16: Ⅰ | B16: 先天異常、周産期の異常、成長・発達の異常 | C16: =COUNTIF(出題基準の網羅!$A$2:$A$1483,A16) -> 82 | D16: =COUNTIFS(出題基準の網羅!$A$2:$A$1483,A16,出題基準の網羅!$F$2:$F$1483,"a") -> 20 | E16: =COUNTIFS(出題基準の網羅!$A$2:$A$1483,A16,出題基準の網羅!$H$2:$H$1483,"あり") -> 4 | F16: =IF(C16=0,0,E16/C16) -> 0.048780488 | G16: =COUNTIFS(出題基準の網羅!$A$2:$A$1483,A16,出題基準の網羅!$F$2:$F$1483,"a",出題基準の網羅!$H$2:$H$1483,"なし") -> 19
A17: Ⅱ | B17: 精神・心身医学的疾患 | C17: =COUNTIF(出題基準の網羅!$A$2:$A$1483,A17) -> 54 | D17: =COUNTIFS(出題基準の網羅!$A$2:$A$1483,A17,出題基準の網羅!$F$2:$F$1483,"a") -> 22 | E17: =COUNTIFS(出題基準の網羅!$A$2:$A$1483,A17,出題基準の網羅!$H$2:$H$1483,"あり") -> 4 | F17: =IF(C17=0,0,E17/C17) -> 0.074074074 | G17: =COUNTIFS(出題基準の網羅!$A$2:$A$1483,A17,出題基準の網羅!$F$2:$F$1483,"a",出題基準の網羅!$H$2:$H$1483,"なし") -> 19
A18: Ⅲ | B18: 皮膚・頭頸部疾患 | C18: =COUNTIF(出題基準の網羅!$A$2:$A$1483,A18) -> 257 | D18: =COUNTIFS(出題基準の網羅!$A$2:$A$1483,A18,出題基準の網羅!$F$2:$F$1483,"a") -> 96 | E18: =COUNTIFS(出題基準の網羅!$A$2:$A$1483,A18,出題基準の網羅!$H$2:$H$1483,"あり") -> 248 | F18: =IF(C18=0,0,E18/C18) -> 0.96498054 | G18: =COUNTIFS(出題基準の網羅!$A$2:$A$1483,A18,出題基準の網羅!$F$2:$F$1483,"a",出題基準の網羅!$H$2:$H$1483,"なし") -> 0
A19: Ⅳ | B19: 呼吸器・胸壁・縦隔疾患 | C19: =COUNTIF(出題基準の網羅!$A$2:$A$1483,A19) -> 86 | D19: =COUNTIFS(出題基準の網羅!$A$2:$A$1483,A19,出題基準の網羅!$F$2:$F$1483,"a") -> 41 | E19: =COUNTIFS(出題基準の網羅!$A$2:$A$1483,A19,出題基準の網羅!$H$2:$H$1483,"あり") -> 86 | F19: =IF(C19=0,0,E19/C19) -> 1 | G19: =COUNTIFS(出題基準の網羅!$A$2:$A$1483,A19,出題基準の網羅!$F$2:$F$1483,"a",出題基準の網羅!$H$2:$H$1483,"なし") -> 0
A20: Ⅴ | B20: 心臓・脈管疾患 | C20: =COUNTIF(出題基準の網羅!$A$2:$A$1483,A20) -> 85 | D20: =COUNTIFS(出題基準の網羅!$A$2:$A$1483,A20,出題基準の網羅!$F$2:$F$1483,"a") -> 51 | E20: =COUNTIFS(出題基準の網羅!$A$2:$A$1483,A20,出題基準の網羅!$H$2:$H$1483,"あり") -> 73 | F20: =IF(C20=0,0,E20/C20) -> 0.85882353 | G20: =COUNTIFS(出題基準の網羅!$A$2:$A$1483,A20,出題基準の網羅!$F$2:$F$1483,"a",出題基準の網羅!$H$2:$H$1483,"なし") -> 5
A21: Ⅵ | B21: 消化器・腹壁・腹膜疾患 | C21: =COUNTIF(出題基準の網羅!$A$2:$A$1483,A21) -> 134 | D21: =COUNTIFS(出題基準の網羅!$A$2:$A$1483,A21,出題基準の網羅!$F$2:$F$1483,"a") -> 66 | E21: =COUNTIFS(出題基準の網羅!$A$2:$A$1483,A21,出題基準の網羅!$H$2:$H$1483,"あり") -> 65 | F21: =IF(C21=0,0,E21/C21) -> 0.48507463 | G21: =COUNTIFS(出題基準の網羅!$A$2:$A$1483,A21,出題基準の網羅!$F$2:$F$1483,"a",出題基準の網羅!$H$2:$H$1483,"なし") -> 21
A22: Ⅶ | B22: 血液・造血器疾患 | C22: =COUNTIF(出題基準の網羅!$A$2:$A$1483,A22) -> 62 | D22: =COUNTIFS(出題基準の網羅!$A$2:$A$1483,A22,出題基準の網羅!$F$2:$F$1483,"a") -> 23 | E22: =COUNTIFS(出題基準の網羅!$A$2:$A$1483,A22,出題基準の網羅!$H$2:$H$1483,"あり") -> 62 | F22: =IF(C22=0,0,E22/C22) -> 1 | G22: =COUNTIFS(出題基準の網羅!$A$2:$A$1483,A22,出題基準の網羅!$F$2:$F$1483,"a",出題基準の網羅!$H$2:$H$1483,"なし") -> 0
A23: Ⅷ | B23: 腎・泌尿器・生殖器疾患 | C23: =COUNTIF(出題基準の網羅!$A$2:$A$1483,A23) -> 177 | D23: =COUNTIFS(出題基準の網羅!$A$2:$A$1483,A23,出題基準の網羅!$F$2:$F$1483,"a") -> 85 | E23: =COUNTIFS(出題基準の網羅!$A$2:$A$1483,A23,出題基準の網羅!$H$2:$H$1483,"あり") -> 175 | F23: =IF(C23=0,0,E23/C23) -> 0.98870056 | G23: =COUNTIFS(出題基準の網羅!$A$2:$A$1483,A23,出題基準の網羅!$F$2:$F$1483,"a",出題基準の網羅!$H$2:$H$1483,"なし") -> 0
A24: Ⅸ | B24: 神経・運動器疾患 | C24: =COUNTIF(出題基準の網羅!$A$2:$A$1483,A24) -> 228 | D24: =COUNTIFS(出題基準の網羅!$A$2:$A$1483,A24,出題基準の網羅!$F$2:$F$1483,"a") -> 87 | E24: =COUNTIFS(出題基準の網羅!$A$2:$A$1483,A24,出題基準の網羅!$H$2:$H$1483,"あり") -> 228 | F24: =IF(C24=0,0,E24/C24) -> 1 | G24: =COUNTIFS(出題基準の網羅!$A$2:$A$1483,A24,出題基準の網羅!$F$2:$F$1483,"a",出題基準の網羅!$H$2:$H$1483,"なし") -> 0
A25: Ⅹ | B25: 内分泌・代謝・栄養・乳腺疾患 | C25: =COUNTIF(出題基準の網羅!$A$2:$A$1483,A25) -> 100 | D25: =COUNTIFS(出題基準の網羅!$A$2:$A$1483,A25,出題基準の網羅!$F$2:$F$1483,"a") -> 30 | E25: =COUNTIFS(出題基準の網羅!$A$2:$A$1483,A25,出題基準の網羅!$H$2:$H$1483,"あり") -> 99 | F25: =IF(C25=0,0,E25/C25) -> 0.99 | G25: =COUNTIFS(出題基準の網羅!$A$2:$A$1483,A25,出題基準の網羅!$F$2:$F$1483,"a",出題基準の網羅!$H$2:$H$1483,"なし") -> 0
A26: Ⅺ | B26: アレルギー性疾患、膠原病、免疫病 | C26: =COUNTIF(出題基準の網羅!$A$2:$A$1483,A26) -> 65 | D26: =COUNTIFS(出題基準の網羅!$A$2:$A$1483,A26,出題基準の網羅!$F$2:$F$1483,"a") -> 30 | E26: =COUNTIFS(出題基準の網羅!$A$2:$A$1483,A26,出題基準の網羅!$H$2:$H$1483,"あり") -> 41 | F26: =IF(C26=0,0,E26/C26) -> 0.63076923 | G26: =COUNTIFS(出題基準の網羅!$A$2:$A$1483,A26,出題基準の網羅!$F$2:$F$1483,"a",出題基準の網羅!$H$2:$H$1483,"なし") -> 5
A27: Ⅻ | B27: 感染性疾患 | C27: =COUNTIF(出題基準の網羅!$A$2:$A$1483,A27) -> 87 | D27: =COUNTIFS(出題基準の網羅!$A$2:$A$1483,A27,出題基準の網羅!$F$2:$F$1483,"a") -> 55 | E27: =COUNTIFS(出題基準の網羅!$A$2:$A$1483,A27,出題基準の網羅!$H$2:$H$1483,"あり") -> 87 | F27: =IF(C27=0,0,E27/C27) -> 1 | G27: =COUNTIFS(出題基準の網羅!$A$2:$A$1483,A27,出題基準の網羅!$F$2:$F$1483,"a",出題基準の網羅!$H$2:$H$1483,"なし") -> 0
A28: ⅩⅢ | B28: 生活環境因子・職業性因子による疾患 | C28: =COUNTIF(出題基準の網羅!$A$2:$A$1483,A28) -> 65 | D28: =COUNTIFS(出題基準の網羅!$A$2:$A$1483,A28,出題基準の網羅!$F$2:$F$1483,"a") -> 37 | E28: =COUNTIFS(出題基準の網羅!$A$2:$A$1483,A28,出題基準の網羅!$H$2:$H$1483,"あり") -> 2 | F28: =IF(C28=0,0,E28/C28) -> 0.030769231 | G28: =COUNTIFS(出題基準の網羅!$A$2:$A$1483,A28,出題基準の網羅!$F$2:$F$1483,"a",出題基準の網羅!$H$2:$H$1483,"なし") -> 35
A29: 計 | C29: =SUM(C16:C28) -> 1482 | D29: =SUM(D16:D28) -> 643 | E29: =SUM(E16:E28) -> 1174 | F29: =IF(C29=0,0,E29/C29) -> 0.79217274 | G29: =SUM(G16:G28) -> 104
A31: ■ 分野・接頭辞ごとの件数
A32: 分野 | B32: 接頭辞 | C32: 範囲 | D32: 有効 | E32: 廃止 | F32: 監修済み | G32: OPEN | H32: RESTRICTED | I32: GOV_JP | J32: GOV_US | K32: UNKNOWN
A33: 消化器 | B33: HP | C33: H. pylori関連疾患 | D33: =COUNTIFS(カード一覧!$C$2:$C$3170,B33,カード一覧!$N$2:$N$3170,"<>retired") -> 20 | E33: =COUNTIFS(カード一覧!$C$2:$C$3170,B33,カード一覧!$N$2:$N$3170,"retired") -> 0 | F33: =COUNTIFS(カード一覧!$C$2:$C$3170,B33,カード一覧!$N$2:$N$3170,"verified_expert") -> 0 | G33: =COUNTIFS(カード一覧!$C$2:$C$3170,B33,カード一覧!$N$2:$N$3170,"<>retired",カード一覧!$M$2:$M$3170,"OPEN") -> 10 | H33: =COUNTIFS(カード一覧!$C$2:$C$3170,B33,カード一覧!$N$2:$N$3170,"<>retired",カード一覧!$M$2:$M$3170,"RESTRICTED") -> 6 | I33: =COUNTIFS(カード一覧!$C$2:$C$3170,B33,カード一覧!$N$2:$N$3170,"<>retired",カード一覧!$M$2:$M$3170,"GOV_JP") -> 0 | J33: =COUNTIFS(カード一覧!$C$2:$C$3170,B33,カード一覧!$N$2:$N$3170,"<>retired",カード一覧!$M$2:$M$3170,"GOV_US") -> 0 | K33: =COUNTIFS(カード一覧!$C$2:$C$3170,B33,カード一覧!$N$2:$N$3170,"<>retired",カード一覧!$M$2:$M$3170,"UNKNOWN") -> 4
A34: 消化器 | B34: UG | C34: 上部消化管出血 | D34: =COUNTIFS(カード一覧!$C$2:$C$3170,B34,カード一覧!$N$2:$N$3170,"<>retired") -> 18 | E34: =COUNTIFS(カード一覧!$C$2:$C$3170,B34,カード一覧!$N$2:$N$3170,"retired") -> 0 | F34: =COUNTIFS(カード一覧!$C$2:$C$3170,B34,カード一覧!$N$2:$N$3170,"verified_expert") -> 0 | G34: =COUNTIFS(カード一覧!$C$2:$C$3170,B34,カード一覧!$N$2:$N$3170,"<>retired",カード一覧!$M$2:$M$3170,"OPEN") -> 2 | H34: =COUNTIFS(カード一覧!$C$2:$C$3170,B34,カード一覧!$N$2:$N$3170,"<>retired",カード一覧!$M$2:$M$3170,"RESTRICTED") -> 10 | I34: =COUNTIFS(カード一覧!$C$2:$C$3170,B34,カード一覧!$N$2:$N$3170,"<>retired",カード一覧!$M$2:$M$3170,"GOV_JP") -> 0 | J34: =COUNTIFS(カード一覧!$C$2:$C$3170,B34,カード一覧!$N$2:$N$3170,"<>retired",カード一覧!$M$2:$M$3170,"GOV_US") -> 0 | K34: =COUNTIFS(カード一覧!$C$2:$C$3170,B34,カード一覧!$N$2:$N$3170,"<>retired",カード一覧!$M$2:$M$3170,"UNKNOWN") -> 6
A35: 消化器 | B35: ES | C35: 食道 | D35: =COUNTIFS(カード一覧!$C$2:$C$3170,B35,カード一覧!$N$2:$N$3170,"<>retired") -> 89 | E35: =COUNTIFS(カード一覧!$C$2:$C$3170,B35,カード一覧!$N$2:$N$3170,"retired") -> 4 | F35: =COUNTIFS(カード一覧!$C$2:$C$3170,B35,カード一覧!$N$2:$N$3170,"verified_expert") -> 0 | G35: =COUNTIFS(カード一覧!$C$2:$C$3170,B35,カード一覧!$N$2:$N$3170,"<>retired",カード一覧!$M$2:$M$3170,"OPEN") -> 30 | H35: =COUNTIFS(カード一覧!$C$2:$C$3170,B35,カード一覧!$N$2:$N$3170,"<>retired",カード一覧!$M$2:$M$3170,"RESTRICTED") -> 47 | I35: =COUNTIFS(カード一覧!$C$2:$C$3170,B35,カード一覧!$N$2:$N$3170,"<>retired",カード一覧!$M$2:$M$3170,"GOV_JP") -> 2 | J35: =COUNTIFS(カード一覧!$C$2:$C$3170,B35,カード一覧!$N$2:$N$3170,"<>retired",カード一覧!$M$2:$M$3170,"GOV_US") -> 0 | K35: =COUNTIFS(カード一覧!$C$2:$C$3170,B35,カード一覧!$N$2:$N$3170,"<>retired",カード一覧!$M$2:$M$3170,"UNKNOWN") -> 10
A36: 消化器 | B36: GD | C36: 胃・十二指腸 | D36: =COUNTIFS(カード一覧!$C$2:$C$3170,B36,カード一覧!$N$2:$N$3170,"<>retired") -> 94 | E36: =COUNTIFS(カード一覧!$C$2:$C$3170,B36,カード一覧!$N$2:$N$3170,"retired") -> 1 | F36: =COUNTIFS(カード一覧!$C$2:$C$3170,B36,カード一覧!$N$2:$N$3170,"verified_expert") -> 0 | G36: =COUNTIFS(カード一覧!$C$2:$C$3170,B36,カード一覧!$N$2:$N$3170,"<>retired",カード一覧!$M$2:$M$3170,"OPEN") -> 71 | H36: =COUNTIFS(カード一覧!$C$2:$C$3170,B36,カード一覧!$N$2:$N$3170,"<>retired",カード一覧!$M$2:$M$3170,"RESTRICTED") -> 15 | I36: =COUNTIFS(カード一覧!$C$2:$C$3170,B36,カード一覧!$N$2:$N$3170,"<>retired",カード一覧!$M$2:$M$3170,"GOV_JP") -> 5 | J36: =COUNTIFS(カード一覧!$C$2:$C$3170,B36,カード一覧!$N$2:$N$3170,"<>retired",カード一覧!$M$2:$M$3170,"GOV_US") -> 1 | K36: =COUNTIFS(カード一覧!$C$2:$C$3170,B36,カード一覧!$N$2:$N$3170,"<>retired",カード一覧!$M$2:$M$3170,"UNKNOWN") -> 2
A37: 消化器 | B37: IN | C37: 小腸・大腸 | D37: =COUNTIFS(カード一覧!$C$2:$C$3170,B37,カード一覧!$N$2:$N$3170,"<>retired") -> 89 | E37: =COUNTIFS(カード一覧!$C$2:$C$3170,B37,カード一覧!$N$2:$N$3170,"retired") -> 0 | F37: =COUNTIFS(カード一覧!$C$2:$C$3170,B37,カード一覧!$N$2:$N$3170,"verified_expert") -> 0 | G37: =COUNTIFS(カード一覧!$C$2:$C$3170,B37,カード一覧!$N$2:$N$3170,"<>retired",カード一覧!$M$2:$M$3170,"OPEN") -> 39 | H37: =COUNTIFS(カード一覧!$C$2:$C$3170,B37,カード一覧!$N$2:$N$3170,"<>retired",カード一覧!$M$2:$M$3170,"RESTRICTED") -> 20 | I37: =COUNTIFS(カード一覧!$C$2:$C$3170,B37,カード一覧!$N$2:$N$3170,"<>retired",カード一覧!$M$2:$M$3170,"GOV_JP") -> 13 | J37: =COUNTIFS(カード一覧!$C$2:$C$3170,B37,カード一覧!$N$2:$N$3170,"<>retired",カード一覧!$M$2:$M$3170,"GOV_US") -> 11 | K37: =COUNTIFS(カード一覧!$C$2:$C$3170,B37,カード一覧!$N$2:$N$3170,"<>retired",カード一覧!$M$2:$M$3170,"UNKNOWN") -> 6
A38: 消化器 | B38: LV | C38: 肝 | D38: =COUNTIFS(カード一覧!$C$2:$C$3170,B38,カード一覧!$N$2:$N$3170,"<>retired") -> 104 | E38: =COUNTIFS(カード一覧!$C$2:$C$3170,B38,カード一覧!$N$2:$N$3170,"retired") -> 0 | F38: =COUNTIFS(カード一覧!$C$2:$C$3170,B38,カード一覧!$N$2:$N$3170,"verified_expert") -> 0 | G38: =COUNTIFS(カード一覧!$C$2:$C$3170,B38,カード一覧!$N$2:$N$3170,"<>retired",カード一覧!$M$2:$M$3170,"OPEN") -> 34 | H38: =COUNTIFS(カード一覧!$C$2:$C$3170,B38,カード一覧!$N$2:$N$3170,"<>retired",カード一覧!$M$2:$M$3170,"RESTRICTED") -> 23 | I38: =COUNTIFS(カード一覧!$C$2:$C$3170,B38,カード一覧!$N$2:$N$3170,"<>retired",カード一覧!$M$2:$M$3170,"GOV_JP") -> 26 | J38: =COUNTIFS(カード一覧!$C$2:$C$3170,B38,カード一覧!$N$2:$N$3170,"<>retired",カード一覧!$M$2:$M$3170,"GOV_US") -> 17 | K38: =COUNTIFS(カード一覧!$C$2:$C$3170,B38,カード一覧!$N$2:$N$3170,"<>retired",カード一覧!$M$2:$M$3170,"UNKNOWN") -> 4
A39: 消化器 | B39: BP | C39: 胆・膵 | D39: =COUNTIFS(カード一覧!$C$2:$C$3170,B39,カード一覧!$N$2:$N$3170,"<>retired") -> 68 | E39: =COUNTIFS(カード一覧!$C$2:$C$3170,B39,カード一覧!$N$2:$N$3170,"retired") -> 0 | F39: =COUNTIFS(カード一覧!$C$2:$C$3170,B39,カード一覧!$N$2:$N$3170,"verified_expert") -> 0 | G39: =COUNTIFS(カード一覧!$C$2:$C$3170,B39,カード一覧!$N$2:$N$3170,"<>retired",カード一覧!$M$2:$M$3170,"OPEN") -> 0 | H39: =COUNTIFS(カード一覧!$C$2:$C$3170,B39,カード一覧!$N$2:$N$3170,"<>retired",カード一覧!$M$2:$M$3170,"RESTRICTED") -> 18 | I39: =COUNTIFS(カード一覧!$C$2:$C$3170,B39,カード一覧!$N$2:$N$3170,"<>retired",カード一覧!$M$2:$M$3170,"GOV_JP") -> 12 | J39: =COUNTIFS(カード一覧!$C$2:$C$3170,B39,カード一覧!$N$2:$N$3170,"<>retired",カード一覧!$M$2:$M$3170,"GOV_US") -> 12 | K39: =COUNTIFS(カード一覧!$C$2:$C$3170,B39,カード一覧!$N$2:$N$3170,"<>retired",カード一覧!$M$2:$M$3170,"UNKNOWN") -> 26
A40: 消化器 | B40: AB | C40: 腹膜・腹壁・急性腹症 | D40: =COUNTIFS(カード一覧!$C$2:$C$3170,B40,カード一覧!$N$2:$N$3170,"<>retired") -> 93 | E40: =COUNTIFS(カード一覧!$C$2:$C$3170,B40,カード一覧!$N$2:$N$3170,"retired") -> 0 | F40: =COUNTIFS(カード一覧!$C$2:$C$3170,B40,カード一覧!$N$2:$N$3170,"verified_expert") -> 0 | G40: =COUNTIFS(カード一覧!$C$2:$C$3170,B40,カード一覧!$N$2:$N$3170,"<>retired",カード一覧!$M$2:$M$3170,"OPEN") -> 24 | H40: =COUNTIFS(カード一覧!$C$2:$C$3170,B40,カード一覧!$N$2:$N$3170,"<>retired",カード一覧!$M$2:$M$3170,"RESTRICTED") -> 69 | I40: =COUNTIFS(カード一覧!$C$2:$C$3170,B40,カード一覧!$N$2:$N$3170,"<>retired",カード一覧!$M$2:$M$3170,"GOV_JP") -> 0 | J40: =COUNTIFS(カード一覧!$C$2:$C$3170,B40,カード一覧!$N$2:$N$3170,"<>retired",カード一覧!$M$2:$M$3170,"GOV_US") -> 0 | K40: =COUNTIFS(カード一覧!$C$2:$C$3170,B40,カード一覧!$N$2:$N$3170,"<>retired",カード一覧!$M$2:$M$3170,"UNKNOWN") -> 0
A41: 消化器 | B41: XS | C41: 症候・検査・栄養 | D41: =COUNTIFS(カード一覧!$C$2:$C$3170,B41,カード一覧!$N$2:$N$3170,"<>retired") -> 37 | E41: =COUNTIFS(カード一覧!$C$2:$C$3170,B41,カード一覧!$N$2:$N$3170,"retired") -> 0 | F41: =COUNTIFS(カード一覧!$C$2:$C$3170,B41,カード一覧!$N$2:$N$3170,"verified_expert") -> 0 | G41: =COUNTIFS(カード一覧!$C$2:$C$3170,B41,カード一覧!$N$2:$N$3170,"<>retired",カード一覧!$M$2:$M$3170,"OPEN") -> 7 | H41: =COUNTIFS(カード一覧!$C$2:$C$3170,B41,カード一覧!$N$2:$N$3170,"<>retired",カード一覧!$M$2:$M$3170,"RESTRICTED") -> 24 | I41: =COUNTIFS(カード一覧!$C$2:$C$3170,B41,カード一覧!$N$2:$N$3170,"<>retired",カード一覧!$M$2:$M$3170,"GOV_JP") -> 0 | J41: =COUNTIFS(カード一覧!$C$2:$C$3170,B41,カード一覧!$N$2:$N$3170,"<>retired",カード一覧!$M$2:$M$3170,"GOV_US") -> 0 | K41: =COUNTIFS(カード一覧!$C$2:$C$3170,B41,カード一覧!$N$2:$N$3170,"<>retired",カード一覧!$M$2:$M$3170,"UNKNOWN") -> 6
A42: 消化器 | B42: NG | C42: 神経消化器病 | D42: =COUNTIFS(カード一覧!$C$2:$C$3170,B42,カード一覧!$N$2:$N$3170,"<>retired") -> 240 | E42: =COUNTIFS(カード一覧!$C$2:$C$3170,B42,カード一覧!$N$2:$N$3170,"retired") -> 0 | F42: =COUNTIFS(カード一覧!$C$2:$C$3170,B42,カード一覧!$N$2:$N$3170,"verified_expert") -> 0 | G42: =COUNTIFS(カード一覧!$C$2:$C$3170,B42,カード一覧!$N$2:$N$3170,"<>retired",カード一覧!$M$2:$M$3170,"OPEN") -> 41 | H42: =COUNTIFS(カード一覧!$C$2:$C$3170,B42,カード一覧!$N$2:$N$3170,"<>retired",カード一覧!$M$2:$M$3170,"RESTRICTED") -> 155 | I42: =COUNTIFS(カード一覧!$C$2:$C$3170,B42,カード一覧!$N$2:$N$3170,"<>retired",カード一覧!$M$2:$M$3170,"GOV_JP") -> 9 | J42: =COUNTIFS(カード一覧!$C$2:$C$3170,B42,カード一覧!$N$2:$N$3170,"<>retired",カード一覧!$M$2:$M$3170,"GOV_US") -> 19 | K42: =COUNTIFS(カード一覧!$C$2:$C$3170,B42,カード一覧!$N$2:$N$3170,"<>retired",カード一覧!$M$2:$M$3170,"UNKNOWN") -> 16
A43: 循環器 | B43: AR | C43: 不整脈 | D43: =COUNTIFS(カード一覧!$C$2:$C$3170,B43,カード一覧!$N$2:$N$3170,"<>retired") -> 35 | E43: =COUNTIFS(カード一覧!$C$2:$C$3170,B43,カード一覧!$N$2:$N$3170,"retired") -> 0 | F43: =COUNTIFS(カード一覧!$C$2:$C$3170,B43,カード一覧!$N$2:$N$3170,"verified_expert") -> 0 | G43: =COUNTIFS(カード一覧!$C$2:$C$3170,B43,カード一覧!$N$2:$N$3170,"<>retired",カード一覧!$M$2:$M$3170,"OPEN") -> 15 | H43: =COUNTIFS(カード一覧!$C$2:$C$3170,B43,カード一覧!$N$2:$N$3170,"<>retired",カード一覧!$M$2:$M$3170,"RESTRICTED") -> 20 | I43: =COUNTIFS(カード一覧!$C$2:$C$3170,B43,カード一覧!$N$2:$N$3170,"<>retired",カード一覧!$M$2:$M$3170,"GOV_JP") -> 0 | J43: =COUNTIFS(カード一覧!$C$2:$C$3170,B43,カード一覧!$N$2:$N$3170,"<>retired",カード一覧!$M$2:$M$3170,"GOV_US") -> 0 | K43: =COUNTIFS(カード一覧!$C$2:$C$3170,B43,カード一覧!$N$2:$N$3170,"<>retired",カード一覧!$M$2:$M$3170,"UNKNOWN") -> 0
...

Sheet カード一覧
A1: ID | B1: 分野 | C1: 接頭辞 | D1: 主題（subdomain） | E1: 主張文 | F1: 地域 | G1: 出題基準（医学各論） | H1: コアカリ | I1: 出典番号 | J1: 出典 | K1: DOI | L1: PMID | M1: ライセンス区分 | N1: 状態 | O1: 置き換え先 | P1: 作成日 | Q1: 不確かさ（uncertainty）
A2: HP-001 | B2: 消化器 | C2: HP | E2: 2018〜2020年に日本国内で集めたH. pylori臨床分離株では、クラリスロマイシン耐性が35.5%、アモキシシリン耐性が2.7%、メトロニダゾール耐性が4.2%だった。 | F2: JP | G2: 医学各論 Ⅻ-2-B-⑧（ヘリコバクター・ピロリ感染症、a） | J2: Okimoto T et al. Helicobacter 2024;29:e13028 | K2: 10.1111/hel.13028 | M2: RESTRICTED | N2: draft | P2: 2026-10-10
A3: HP-002 | B3: 消化器 | C3: HP | E3: 日本の第III相二重盲検RCTでは、一次除菌（三剤）の除菌率がボノプラザン群92.6%、ランソプラゾール群75.9%だった。 | F3: JP | G3: 医学各論 Ⅻ-2-B-⑧（ヘリコバクター・ピロリ感染症、a） | J3: Murakami K et al. Gut 2016;65:1439-46 | K3: 10.1136/gutjnl-2015-311304 | L3: 26935876 | M3: UNKNOWN | N3: draft | P3: 2026-10-10 | Q3: DOI・PMIDはPubMedのコメント記事（PMID 27210791）とClinicalTrials.gov NCT04901663の文献リストで確認。ライセンスは要確認
A4: HP-003 | B4: 消化器 | C4: HP | E4: 同じRCTのCAM耐性株感染例では、除菌率がボノプラザン三剤で82.0%、ランソプラゾール三剤で40.0%だった（p<0.0001）。 | F4: JP | G4: 医学各論 Ⅻ-2-B-⑧（ヘリコバクター・ピロリ感染症、a） | J4: Murakami 2016 原著本文（PMC5036253、online supplementary table S1参照）; Frontiers Pharmacol 2018 (10.3389/fphar.2018.01560) | M4: UNKNOWN | N4: draft | P4: 2026-10-10 | Q4: 数値は原著本文で確認済み。ライセンスは要確認
A5: HP-004 | B5: 消化器 | C5: HP | E5: JSGE 2026は、一次除菌ではPPIよりボノプラザンを含む三剤療法を用いることを強く推奨している（エビデンスA、7件のRCTのメタ解析）。 | F5: JP | G5: 医学各論 Ⅻ-2-B-⑧（ヘリコバクター・ピロリ感染症、a） | J5: JSGE PUD GL 2026 | K5: 10.1007/s00535-026-02504-3 | M5: OPEN | N5: draft | P5: 2026-10-10
A6: HP-005 | B6: 消化器 | C6: HP | E6: JSGE 2026は、可能であれば一次除菌前にCAM感受性検査を行い、最も高い除菌率が見込めるレジメンを選ぶよう強く推奨している。 | F6: JP | G6: 医学各論 Ⅻ-2-B-⑧（ヘリコバクター・ピロリ感染症、a） | J6: JSGE PUD GL 2026 | K6: 10.1007/s00535-026-02504-3 | M6: OPEN | N6: draft | P6: 2026-10-10
A7: HP-006 | B7: 消化器 | C7: HP | E7: CAM感受性株にはVPZ＋AMPC＋CAMを、CAM耐性株にはPPIまたはVPZ＋AMPC＋MNZを用いることが推奨されている。 | F7: JP | G7: 医学各論 Ⅻ-2-B-⑧（ヘリコバクター・ピロリ感染症、a） | J7: JSGE PUD GL 2026 | K7: 10.1007/s00535-026-02504-3 | M7: OPEN | N7: draft | P7: 2026-10-10
A8: HP-007 | B8: 消化器 | C8: HP | E8: 日本の二次除菌の推奨レジメンは、標準量PPIまたはVPZ 20 mg、AMPC 750 mg、MNZ 250 mgを1日2回・1週間投与するもので、PPIとVPZで除菌率は同等とされる。 | F8: JP | G8: 医学各論 Ⅻ-2-B-⑧（ヘリコバクター・ピロリ感染症、a） | J8: JSGE PUD GL 2026 | K8: 10.1007/s00535-026-02504-3 | M8: OPEN | N8: draft | P8: 2026-10-10 | Q8: 用量は保険診療上の用法と照合を要確認
A9: HP-008 | B9: 消化器 | C9: HP | E9: 欧州のMaastricht VI/Florenceコンセンサスは、感受性が不明な場合やCAM耐性率が15%を超える地域では、経験的一次治療として14日間のビスマス4剤療法を推奨している。 | F9: EU | G9: 医学各論 Ⅻ-2-B-⑧（ヘリコバクター・ピロリ感染症、a） | J9: Malfertheiner P et al. Gut 2022;71:1724-62 | K9: 10.1136/gutjnl-2022-327745 | L9: 35944925 | M9: RESTRICTED | N9: draft | P9: 2026-10-10 | Q9: 推奨文の詳細は二次文献（Microbiota journal 2023 review）経由。原著で要確認
A10: HP-009 | B10: 消化器 | C10: HP | E10: 米国ACG 2024は、未治療例の選択肢として最適化ビスマス4剤療法を優先し、感受性が確認されない限りCAMやレボフロキサシンを含むレジメンは避けるよう求めている。 | F10: US | G10: 医学各論 Ⅻ-2-B-⑧（ヘリコバクター・ピロリ感染症、a） | J10: Chey WD et al. Am J Gastroenterol 2024;119:1730-53（要旨はJCAG誌の解説（CC BY）経由） | K10: 10.14309/ajg.0000000000002968 | M10: RESTRICTED | N10: draft | P10: 2026-10-10
A11: HP-010 | B11: 消化器 | C11: HP | E11: ACG 2024は、未治療例の選択肢として、ビスマス4剤のほか、リファブチン三剤、VPZ＋AMPC二剤、VPZ三剤（いずれも14日間）を挙げている。 | F11: US | G11: 医学各論 Ⅻ-2-B-⑧（ヘリコバクター・ピロリ感染症、a） | J11: JCAG 2025 commentary（academic.oup.com/jcag/article/8/3/85/8125707） | M11: OPEN | N11: draft | P11: 2026-10-10
A12: HP-011 | B12: 消化器 | C12: HP | E12: PPI服用中は尿素呼気試験、迅速ウレアーゼ試験、ペプシノゲン値の信頼性が下がるため、診断にはこれらを用いない。 | F12: JP | G12: 医学各論 Ⅻ-2-B-⑧（ヘリコバクター・ピロリ感染症、a） | J12: JSHR GL 2024 英語版 | K12: 10.1007/s00535-026-02379-4 | M12: OPEN | N12: draft | P12: 2026-10-10
A13: HP-012 | B13: 消化器 | C13: HP | E13: 除菌判定の検査前には、PPIを2週間以上、ビスマスと抗菌薬を4週間以上中止し、治療終了から4週間以上あけて判定する。 | F13: US | G13: 医学各論 Ⅻ-2-B-⑧（ヘリコバクター・ピロリ感染症、a） | J13: ACG 2024（Emory大学の要約資料経由） | K13: 10.14309/ajg.0000000000002968 | M13: RESTRICTED | N13: draft | P13: 2026-10-10 | Q13: 日本のJSHR推奨期間との異同を要確認
A14: HP-013 | B14: 消化器 | C14: HP | E14: 尿素呼気試験のカットオフは除菌前で2.5〜3.5‰、除菌後で3.5〜4.0‰が適切とされ、除菌前に2.5‰を用いた場合の感度は96.2〜100%、特異度は83.3〜100%と報告されている。 | F14: JP | G14: 医学各論 Ⅻ-2-B-⑧（ヘリコバクター・ピロリ感染症、a） | J14: JSHR GL 2024 英語版 | K14: 10.1007/s00535-026-02379-4 | M14: OPEN | N14: draft | P14: 2026-10-10
A15: HP-014 | B15: 消化器 | C15: HP | E15: 京都分類に基づく内視鏡所見のうち、現感染を最も強く示すのはびまん性発赤（診断オッズ比26.8）で、粘膜腫脹13.3、白濁粘液10.2、皺襞腫大8.6が続く。 | F15: JP | G15: 医学各論 Ⅻ-2-B-⑧（ヘリコバクター・ピロリ感染症、a） | J15: Yoshii S et al. Dig Endosc 2020;32:74-83（JSHR GL 2024で引用） | K15: 10.1007/s00535-026-02379-4（引用元） | M15: UNKNOWN | N15: draft | P15: 2026-10-10 | Q15: RACに関する誤解例は専門医確認を要する
A16: HP-015 | B16: 消化器 | C16: HP | E16: JSHR 2024は、H. pylori感染症はすべて除菌の適応であるという基本方針を維持している。 | F16: JP | G16: 医学各論 Ⅻ-2-B-⑧（ヘリコバクター・ピロリ感染症、a） | J16: JSHR GL 2024 英語版（抄録） | K16: 10.1007/s00535-026-02379-4 | M16: OPEN | N16: draft | P16: 2026-10-10
A17: HP-016 | B17: 消化器 | C17: HP | E17: 胃癌予防の観点からは、より若い年齢での除菌が推奨され、日本では中学生の時期での検査と除菌が予防戦略として強調されている。 | F17: JP | G17: 医学各論 Ⅻ-2-B-⑧（ヘリコバクター・ピロリ感染症、a） | J17: JSHR GL 2024 英語版 | K17: 10.1007/s00535-026-02379-4 | M17: OPEN | N17: draft | P17: 2026-10-10 | Q17: 推奨の強さとエビデンスレベルは要確認
A18: HP-017 | B18: 消化器 | C18: HP | E18: 京都グローバルコンセンサスは、H. pylori胃炎を症状の有無にかかわらず感染症として位置づけた。 | F18: global | G18: 医学各論 Ⅻ-2-B-⑧（ヘリコバクター・ピロリ感染症、a） | J18: Sugano K et al. Gut 2015;64:1353-67 | K18: 10.1136/gutjnl-2015-309252 | L18: 26187502 | M18: RESTRICTED | N18: draft | P18: 2026-10-10 | Q18: 『症状の有無にかかわらず』の表現は原著で要確認
A19: HP-018 | B19: 消化器 | C19: HP | E19: 日本の胃潰瘍患者数は2023年に年間19.4万人、十二指腸潰瘍は2.0万人まで減少し、40年前と比べるとそれぞれ約10分の1、約20分の1になった。 | F19: JP | G19: 医学各論 Ⅻ-2-B-⑧（ヘリコバクター・ピロリ感染症、a） | J19: 厚労省 患者調査2023（JSGE PUD GL 2026の序論で引用） | M19: UNKNOWN | N19: draft | P19: 2026-10-10
A20: HP-019 | B20: 消化器 | C20: HP | E20: H. pylori陰性かつNSAID非使用の消化性潰瘍（特発性潰瘍）と、非H. pyloriヘリコバクター（NHPH）感染による潰瘍の増加が注目されている。 | F20: JP | G20: 医学各論 Ⅻ-2-B-⑧（ヘリコバクター・ピロリ感染症、a） | J20: JSGE PUD GL 2026（抄録） | K20: 10.1007/s00535-026-02504-3 | M20: OPEN | N20: draft | P20: 2026-10-10
A21: HP-020 | B21: 消化器 | C21: HP | E21: H. pylori陽性の限局期胃MALTリンパ腫では、除菌療法が一次治療として位置づけられている。 | F21: JP/EU | G21: 医学各論 Ⅻ-2-B-⑧（ヘリコバクター・ピロリ感染症、a） | J21: JSHR GL 2024（除菌適応疾患の一覧）／Maastricht VI | M21: RESTRICTED | N21: draft | P21: 2026-10-10 | Q21: 該当CQ番号、寛解率の数値、t(11;18)陽性例の扱いは要確認。完全寛解率の一次ソース（メタ解析PMID）は未取得
A22: UG-001 | B22: 消化器 | C22: UG | E22: 救急外来を受診した上部消化管出血のうち、院内での介入または死亡の見逃し率が1%以下となる超低リスク例（例：Glasgow-Blatchfordスコア0〜1）は、入院させず外来フォローで帰宅させることが提案されている。 | F22: US | J22: Laine L et al. Am J Gastroenterol 2021;116:899-917 | K22: 10.14309/ajg.0000000000001245 | L22: 33929377 | M22: RESTRICTED | N22: draft | P22: 2026-10-10
A23: UG-002 | B23: 消化器 | C23: UG | E23: GBS 0の感度の点推定値は99〜100%だが、特異度は8〜22%と低い。 | F23: US | J23: ACG 2021 | K23: 10.14309/ajg.0000000000001245 | M23: RESTRICTED | N23: draft | P23: 2026-10-10
A24: UG-003 | B24: 消化器 | C24: UG | E24: 上部消化管出血の入院患者では、Hb 7 g/dLを閾値とする制限輸血が提案されている。 | F24: US | J24: ACG 2021 | K24: 10.14309/ajg.0000000000001245 | M24: RESTRICTED | N24: draft | P24: 2026-10-10 | Q24: 心血管疾患合併例の具体的な閾値（8 g/dL等）は要確認
A25: UG-004 | B25: 消化器 | C25: UG | E25: 閾値7 g/dLの根拠となった上部消化管出血のRCT（単施設、n=921：制限群461例＜7 g/dL、非制限群460例＜9 g/dL）では、輸血を受けた患者の割合が制限群49%、非制限群86%（P<0.001）で、45日死亡率は5% vs 9%（HR 0.55; 95% CI 0.33–0.92）だった。 | F25: EU(Spain, Hospital de Sant Pau, Barcelona) | J25: Villanueva C et al. N Engl J Med 2013;368(1):11-21（ACG 2021が引用） | L25: 23281973 | M25: RESTRICTED | N25: draft | P25: 2026-10-10 | Q25: PMIDはPubMedの検索結果で確認。DOIは要確認｜［取り込み時］DOIは原本で「要確認」のためnull
A26: UG-005 | B26: 消化器 | C26: UG | E26: システマティックレビューでは、制限輸血によって輸血を受ける患者数が43%減り、臨床的に重要な転帰の悪化は認められなかった。 | F26: global | J26: ACG 2021 | K26: 10.14309/ajg.0000000000001245 | M26: RESTRICTED | N26: draft | P26: 2026-10-10
A27: UG-006 | B27: 消化器 | C27: UG | E27: 非静脈瘤性上部消化管出血では、循環動態を安定させた後、24時間以内に上部内視鏡を行うことが推奨される。 | F27: JP/EU/US | J27: JGES NVUGIB GL 第2版（強い推奨）、ESGE 2021、ACG 2021 | K27: 10.1111/den.15019; 10.1055/a-1369-5274 | M27: RESTRICTED | N27: draft | P27: 2026-10-10
A28: UG-007 | B28: 消化器 | C28: UG | E28: 上部消化管出血が疑われる患者に、スクリーニング目的で経鼻胃管をルーチンに挿入することは推奨されない。 | F28: JP | J28: JGES NVUGIB GL 第2版 | K28: 10.1111/den.15019 | M28: RESTRICTED | N28: draft | P28: 2026-10-10
A29: UG-008 | B29: 消化器 | C29: UG | E29: 重症または活動性出血が続く上部消化管出血では、内視鏡の30〜120分前にエリスロマイシン250 mgを単回静注することが推奨される。 | F29: EU | J29: ESGE 2015/2021、ESGE 2026 | K29: 10.1055/s-0034-1393172; 10.1055/a-2863-8314 | M29: UNKNOWN | N29: draft | P29: 2026-10-10 | Q29: 日本での保険適用外使用である点を要確認
A30: UG-009 | B30: 消化器 | C30: UG | E30: Forrest分類のIa（噴出性出血）、Ib（湧出性出血）、IIa（露出血管）は高リスク所見で内視鏡的止血の対象となる。IIc（平坦な色素斑）とIII（清浄潰瘍底）は再出血リスクが低く、止血処置を要しない。 | F30: global | J30: ESGE 2015 (10.1055/s-0034-1393172)、ACG 2021 | M30: RESTRICTED | N30: draft | P30: 2026-10-10
A31: UG-010 | B31: 消化器 | C31: UG | E31: ESGE 2026は、高リスク所見（FIa・FIb）の消化性潰瘍出血に対し、再出血がより少ないことから、over-the-scope（OTS）クリップ単独を従来の併用療法に代わる一次治療として提案している。 | F31: EU | J31: ESGE 2026（PubMed抄録 PMID 42127996） | K31: 10.1055/a-2863-8314 | M31: UNKNOWN | N31: draft | P31: 2026-10-10
A32: UG-011 | B32: 消化器 | C32: UG | E32: エピネフリン局注のみによる止血は不十分で、他の止血法と併用すべきである。 | F32: global | J32: ESGE 2021／ACG 2021 | M32: RESTRICTED | N32: draft | P32: 2026-10-10 | Q32: 今回取得した資料では文言を確認できていない。要確認
A33: UG-012 | B33: 消化器 | C33: UG | E33: 出血性潰瘍の内視鏡的止血後にPPIを投与すると、再出血、輸血量、入院期間、手術の必要性が減る。用量や投与経路による効果差は乏しいとされる。 | F33: JP | J33: JSGE PUD GL 2026 | K33: 10.1007/s00535-026-02504-3 | M33: OPEN | N33: draft | P33: 2026-10-10
A34: UG-013 | B34: 消化器 | C34: UG | E34: 止血成功後の高リスク潰瘍では、VPZ 40 mgと高用量PPI持続静注（80 mgボーラス後8 mg/時を72時間）を比べた2つのRCTで、再出血率と死亡率に差がなかった。 | F34: Thailand RCT | J34: Geeratragool T et al. Gastroenterology 2024;167:778-87（JSGE 2026経由） | K34: 10.1007/s00535-026-02504-3（引用元） | M34: OPEN | N34: draft | P34: 2026-10-10
A35: UG-014 | B35: 消化器 | C35: UG | E35: 内視鏡治療を行った高リスク潰瘍出血では、高用量PPI（1日80 mg以上）を3日間投与した後、2週間は1日2回のPPIを続けることが提案されている。 | F35: US | J35: ACG 2021（Emory大学の要約資料経由） | K35: 10.14309/ajg.0000000000001245 | M35: RESTRICTED | N35: draft | P35: 2026-10-10 | Q35: 原文の推奨強度は要確認
A36: UG-015 | B36: 消化器 | C36: UG | E36: ESGE 2026は、再出血例にはOTSクリップでの再止血を考慮し、それも不成功なら経カテーテル動脈塞栓術（TAE）、TAEができない・不成功なら手術という順序を推奨している。 | F36: EU | J36: ESGE 2026 | K36: 10.1055/a-2863-8314 | M36: UNKNOWN | N36: draft | P36: 2026-10-10
A37: UG-016 | B37: 消化器 | C37: UG | E37: 心血管疾患の二次予防として低用量アスピリンを服用中の患者が消化性潰瘍出血を起こした場合、再出血リスクが低ければ、内視鏡直後からアスピリンを再開することが推奨される。 | F37: EU | J37: ESGE 2015 | K37: 10.1055/s-0034-1393172 | M37: UNKNOWN | N37: draft | P37: 2026-10-10 | Q37: 最新版での再開時期（即時／3日以内等）は要確認
A38: UG-017 | B38: 消化器 | C38: UG | E38: 抗凝固療法の継続が必要な患者では、血栓塞栓リスクに応じて、臨床的に可能になった時点でできるだけ早く抗凝固薬を再開することが推奨される。 | F38: EU | J38: ESGE 2026 | K38: 10.1055/a-2863-8314 | M38: UNKNOWN | N38: draft | P38: 2026-10-10
A39: UG-018 | B39: 消化器 | C39: UG | E39: 持続的な止血が得られた消化性潰瘍出血では、止血後24時間以内に経口摂取を始め、鉄欠乏や貧血があれば退院前に鉄補充を開始することが提案されている。 | F39: EU | J39: ESGE 2026 | K39: 10.1055/a-2863-8314 | M39: UNKNOWN | N39: draft | P39: 2026-10-10
A40: ES-001 | B40: 消化器 | C40: ES | D40: GERD・NERD・Barrett食道 | E40: 日本消化器病学会のGERD診療ガイドライン第3版（日本語版）は2021年4月に刊行され、GERDを逆流性食道炎（RE）と非びらん性逆流症（NERD）に分けた治療アルゴリズムを導入した。 | F40: 日本 | G40: 医学各論 Ⅵ-1-B-①（胃食道逆流症<GERD>、非びらん性胃食道逆流症<NERD>、a） | H40: PS-02-08-05 (id: JkxnuRY) | J40: Iwakiri K, et al. JSGE GERD guidelines 2021. J Gastroenterol 2022;57:267-285 | K40: 10.1007/s00535-022-01861-z | L40: 35226174 | M40: OPEN | N40: verified_sources | P40: 2026-10-10 | Q40: low
...

Sheet 出典一覧
A1: 出典番号 | B1: 書誌 | C1: DOI | D1: PMID | E1: ライセンス区分 | F1: ライセンス表示 | G1: 使っているカード数
A2: SRC-001 | B2: Kato K, JCOG1109 | D2: 38876133 | E2: RESTRICTED | F2: 非CC | G2: =COUNTIF(カード一覧!$I$2:$I$3170,A2) -> 2
A3: SRC-002 | B3: Kelly RJ, CheckMate 577 | C3: 10.1056/NEJMoa2032125 | E3: RESTRICTED | F3: 非CC | G3: =COUNTIF(カード一覧!$I$2:$I$3170,A3) -> 1
A4: SRC-003 | B4: Doki Y, CheckMate 648 | C4: 10.1056/NEJMoa2111380 | E4: RESTRICTED | F4: 非CC | G4: =COUNTIF(カード一覧!$I$2:$I$3170,A4) -> 1
A5: SRC-004 | B5: Sun JM, KEYNOTE-590 | D5: 34454674 | E5: RESTRICTED | F5: 非CC | G5: =COUNTIF(カード一覧!$I$2:$I$3170,A5) -> 2
A6: SRC-005 | B6: Metges JP, KEYNOTE-590 5年 | E6: RESTRICTED | F6: CC BY-NC-ND 4.0（Crossref） | G6: =COUNTIF(カード一覧!$I$2:$I$3170,A6) -> 0
A7: SRC-006 | B7: Ishihara R, JGES食道ESD/EMR GL | E7: RESTRICTED | F7: Wiley規約（Crossref） | G7: =COUNTIF(カード一覧!$I$2:$I$3170,A7) -> 2
A8: SRC-007 | B8: de Franchis R, Baveno VII | E8: RESTRICTED | F8: Elsevier TDMのみ | G8: =COUNTIF(カード一覧!$I$2:$I$3170,A8) -> 2
A9: SRC-008 | B9: Gralnek IM, ESGE静脈瘤GL | D9: 36174643 | E9: UNKNOWN | F9: 未確認 | G9: =COUNTIF(カード一覧!$I$2:$I$3170,A9) -> 0
A10: SRC-009 | B10: Birk M, ESGE異物GL | D10: 26862844 | E10: UNKNOWN | F10: 未確認 | G10: =COUNTIF(カード一覧!$I$2:$I$3170,A10) -> 4
A11: SRC-010 | B11: Gyawali CP, Lyon 2.0 | C11: 10.1136/gutjnl-2023-330616 | E11: RESTRICTED | F11: CC BY-NC（WUSTLの記録） | G11: =COUNTIF(カード一覧!$I$2:$I$3170,A11) -> 1
A12: SRC-011 | B12: Yadlapati R, Chicago v4.0 | E12: UNKNOWN | F12: 未確認 | G12: =COUNTIF(カード一覧!$I$2:$I$3170,A12) -> 7
A13: SRC-012 | B13: Brooks PJ, Alcohol flushing response | C13: 10.1371/journal.pmed.1000050 | E13: OPEN | F13: CC BY | G13: =COUNTIF(カード一覧!$I$2:$I$3170,A13) -> 1
A14: SRC-013 | B14: Lewis SJ, ALDH2メタ解析 | D14: 16103445 | E14: RESTRICTED | F14: 非CC | G14: =COUNTIF(カード一覧!$I$2:$I$3170,A14) -> 0
A15: SRC-014 | B15: 国立がん研究センター がん統計 | E15: GOV_JP | F15: 元データは政府統計。サイトの規約は未確認 | G15: =COUNTIF(カード一覧!$I$2:$I$3170,A15) -> 1
A16: SRC-015 | B16: 診療報酬点数表 K653-6 | E16: GOV_JP | F16: 告示原本は未閲覧 | G16: =COUNTIF(カード一覧!$I$2:$I$3170,A16) -> 1
A17: SRC-016 | B17: 小野薬品・BMS 適正使用文書 | E17: RESTRICTED | F17: 企業資料 | G17: =COUNTIF(カード一覧!$I$2:$I$3170,A17) -> 1
A18: SRC-017 | B18: 門脈圧亢進症取扱い規約 第3版の記載基準 | E18: RESTRICTED | F18: 非CC | G18: =COUNTIF(カード一覧!$I$2:$I$3170,A18) -> 2
A19: SRC-018 | B19: Yoshiji H, 肝硬変GL 2020 | E19: UNKNOWN | F19: 種別は未確認 | G19: =COUNTIF(カード一覧!$I$2:$I$3170,A19) -> 24
A20: SRC-019 | B20: Verhoeven RHA, CheckMate 577 実臨床 | E20: UNKNOWN | F20: 未確認 | G20: =COUNTIF(カード一覧!$I$2:$I$3170,A20) -> 0
A21: SRC-020 | B21: Contini S, 腐食性傷害の総説 | E21: RESTRICTED | F21: CC BY-NC | G21: =COUNTIF(カード一覧!$I$2:$I$3170,A21) -> 2
A22: SRC-021 | B22: Cheng HT, 成人の腐食性物質摂取 | E22: OPEN | F22: CC BY | G22: =COUNTIF(カード一覧!$I$2:$I$3170,A22) -> 1
A23: SRC-022 | B23: Boerhaave Syndrome—Narrative Review | E23: OPEN | F23: CC BY 4.0 | G23: =COUNTIF(カード一覧!$I$2:$I$3170,A23) -> 3
A24: SRC-023 | B24: HSV/CMV食道共感染の症例と文献レビュー | E24: UNKNOWN | F24: 未確認 | G24: =COUNTIF(カード一覧!$I$2:$I$3170,A24) -> 1
A25: SRC-024 | B25: HSV vs CMV食道炎の内視鏡所見 | C25: 10.1097/MD.0000000000015845 | E25: UNKNOWN | F25: 未確認 | G25: =COUNTIF(カード一覧!$I$2:$I$3170,A25) -> 2
A26: SRC-025 | B26: Werner YB, POEM vs LHM | D26: 31800987 | E26: RESTRICTED | F26: 非CC | G26: =COUNTIF(カード一覧!$I$2:$I$3170,A26) -> 2
A27: SRC-026 | B27: Dellon ES, デュピルマブ EoE | D27: 36546624 | E27: RESTRICTED | F27: 非CC | G27: =COUNTIF(カード一覧!$I$2:$I$3170,A27) -> 1
A28: SRC-027 | B28: Villanueva C, 輸血戦略 | D28: 23281973 | E28: RESTRICTED | F28: 非CC | G28: =COUNTIF(カード一覧!$I$2:$I$3170,A28) -> 1
A29: SRC-028 | B29: Miwa H, et al. Evidence-based clinical practice guidelines for functional dyspepsia 2021. J Gastroenterol 2022;57:47-61 | C29: 10.1007/s00535-021-01843-7 | E29: UNKNOWN | F29: Open access, © 2022 The Author(s)（CC種別は出版社ページで未表示。Crossrefで要確認） | G29: =COUNTIF(カード一覧!$I$2:$I$3170,A29) -> 18
A30: SRC-029 | B30: Japanese Gastric Cancer Association. Japanese Gastric Cancer Treatment Guidelines 2021 (6th edition). Gastric Cancer 2023;26:1-25 | C30: 10.1007/s10120-022-01331-8 | E30: UNKNOWN | F30: Open access, © 2022 The Author(s)（CC種別はCrossrefで要確認） | G30: =COUNTIF(カード一覧!$I$2:$I$3170,A30) -> 2
A31: SRC-030 | B31: Japanese Gastric Cancer Association. Japanese gastric cancer treatment guidelines 2025 (7th edition). Gastric Cancer 2026;29:271-299 | C31: 10.1007/s10120-025-01698-4 | E31: UNKNOWN | F31: Open access, © 2026 The Author(s)（CC種別はCrossrefで要確認） | G31: =COUNTIF(カード一覧!$I$2:$I$3170,A31) -> 23
A32: SRC-031 | B32: Sugimoto M, et al. Evidence-based clinical practice guidelines for peptic ulcer disease 2026. J Gastroenterol 2026;61:1361-1381 | C32: 10.1007/s00535-026-02504-3 | E32: OPEN | F32: CC BY 4.0（パイロット時にCrossrefで確認） | G32: =COUNTIF(カード一覧!$I$2:$I$3170,A32) -> 14
A33: SRC-032 | B33: Hirota S, et al. English version of Japanese Clinical Practice Guidelines 2022 for gastrointestinal stromal tumor (GIST). Int J Clin Oncol 2024;29:647-680 | C33: 10.1007/s10147-024-02488-1 | D33: 38609732 | E33: UNKNOWN | F33: Open access, © 2024 The Author(s)（CC種別はCrossrefで要確認） | G33: =COUNTIF(カード一覧!$I$2:$I$3170,A33) -> 8
A34: SRC-033 | B34: Joensuu H, et al. Adjuvant imatinib for high-risk GI stromal tumor: analysis of a randomized trial. J Clin Oncol 2016;34:244-250 | C34: 10.1200/JCO.2015.62.9170 | D34: 26527782 | E34: RESTRICTED | F34: 非CC（ASCO） | G34: =COUNTIF(カード一覧!$I$2:$I$3170,A34) -> 1
A35: SRC-034 | B35: Janjigian YY, et al. CheckMate 649. Lancet 2021;398:27-40 | C35: 10.1016/S0140-6736(21)00797-2 | D35: 34102137 | E35: RESTRICTED | F35: 非CC（Elsevier） | G35: =COUNTIF(カード一覧!$I$2:$I$3170,A35) -> 1
A36: SRC-035 | B36: Shitara K, et al. SPOTLIGHT. Lancet 2023;401:1655-1668 | C36: 10.1016/S0140-6736(23)00620-7 | D36: 37068504 | E36: RESTRICTED | F36: 非CC（Elsevier） | G36: =COUNTIF(カード一覧!$I$2:$I$3170,A36) -> 1
A37: SRC-036 | B37: 国立がん研究センター がん情報サービス 胃（罹患2026-03-23更新、死亡2026-01-07更新、生存率2026-07-22更新） | E37: GOV_JP | F37: 元データは政府統計。サイト利用規約は要確認 | G37: =COUNTIF(カード一覧!$I$2:$I$3170,A37) -> 1
A38: SRC-037 | B38: 厚生労働省『がん予防重点健康教育及びがん検診実施のための指針』（平成28年2月改正）／厚労省がん検診ページ | E38: GOV_JP | F38: 政府標準利用規約（原文は要確認） | G38: =COUNTIF(カード一覧!$I$2:$I$3170,A38) -> 2
A39: SRC-038 | B39: アステラス製薬 適時開示（2024-07-29）：ゾルベツキシマブ 欧州CHMP販売承認勧告（国内承認日の記載あり） | E39: RESTRICTED | F39: 企業資料（非CC） | G39: =COUNTIF(カード一覧!$I$2:$I$3170,A39) -> 1
A40: SRC-039 | B40: Panzuto F, et al. ENETS 2023 guidance paper for gastroduodenal neuroendocrine tumours (NETs) G1-G3. J Neuroendocrinol 2023;35:e13306 | C40: 10.1111/jne.13306 | E40: UNKNOWN | F40: Open access, © 2023 The Authors（CC種別はCrossrefで要確認） | G40: =COUNTIF(カード一覧!$I$2:$I$3170,A40) -> 1
...

Sheet 出題基準の網羅
A1: 章 | B1: 章の名前 | C1: 大項目 | D1: 番号 | E1: 項目 | F1: レベル | G1: 有効なカード数 | H1: カード
A2: Ⅰ | B2: 先天異常、周産期の異常、成長・発達の異常 | C2: 妊娠の異常 | D2: Ⅰ-1-A-① | E2: 妊娠悪阻 | F2: a | G2: =COUNTIFS(カード一覧!$G$2:$G$3170,"*医学各論 "&D2&"（*",カード一覧!$N$2:$N$3170,"<>retired") -> 0 | H2: =IF(G2>0,"あり","なし") -> なし
A3: Ⅰ | B3: 先天異常、周産期の異常、成長・発達の異常 | C3: 妊娠の異常 | D3: Ⅰ-1-A-② | E3: 異所性妊娠 | F3: a | G3: =COUNTIFS(カード一覧!$G$2:$G$3170,"*医学各論 "&D3&"（*",カード一覧!$N$2:$N$3170,"<>retired") -> 0 | H3: =IF(G3>0,"あり","なし") -> なし
A4: Ⅰ | B4: 先天異常、周産期の異常、成長・発達の異常 | C4: 妊娠の異常 | D4: Ⅰ-1-A-③ | E4: 流産、切迫流産 | F4: a | G4: =COUNTIFS(カード一覧!$G$2:$G$3170,"*医学各論 "&D4&"（*",カード一覧!$N$2:$N$3170,"<>retired") -> 0 | H4: =IF(G4>0,"あり","なし") -> なし
A5: Ⅰ | B5: 先天異常、周産期の異常、成長・発達の異常 | C5: 妊娠の異常 | D5: Ⅰ-1-A-④ | E5: 胞状奇胎 | F5: b | G5: =COUNTIFS(カード一覧!$G$2:$G$3170,"*医学各論 "&D5&"（*",カード一覧!$N$2:$N$3170,"<>retired") -> 0 | H5: =IF(G5>0,"あり","なし") -> なし
A6: Ⅰ | B6: 先天異常、周産期の異常、成長・発達の異常 | C6: 妊娠の異常 | D6: Ⅰ-1-A-⑤ | E6: 頸管無力症 | F6: b | G6: =COUNTIFS(カード一覧!$G$2:$G$3170,"*医学各論 "&D6&"（*",カード一覧!$N$2:$N$3170,"<>retired") -> 0 | H6: =IF(G6>0,"あり","なし") -> なし
A7: Ⅰ | B7: 先天異常、周産期の異常、成長・発達の異常 | C7: 妊娠の異常 | D7: Ⅰ-1-A-⑥ | E7: 不育症、習慣流産 | F7: b | G7: =COUNTIFS(カード一覧!$G$2:$G$3170,"*医学各論 "&D7&"（*",カード一覧!$N$2:$N$3170,"<>retired") -> 1 | H7: =IF(G7>0,"あり","なし") -> あり
A8: Ⅰ | B8: 先天異常、周産期の異常、成長・発達の異常 | C8: 妊娠の異常 | D8: Ⅰ-1-B-① | E8: 妊娠高血圧症候群、子癇、HELLP症候群、加重型妊娠高血圧腎症 | F8: a | G8: =COUNTIFS(カード一覧!$G$2:$G$3170,"*医学各論 "&D8&"（*",カード一覧!$N$2:$N$3170,"<>retired") -> 0 | H8: =IF(G8>0,"あり","なし") -> なし
A9: Ⅰ | B9: 先天異常、周産期の異常、成長・発達の異常 | C9: 妊娠の異常 | D9: Ⅰ-1-B-② | E9: 早産、切迫早産 | F9: a | G9: =COUNTIFS(カード一覧!$G$2:$G$3170,"*医学各論 "&D9&"（*",カード一覧!$N$2:$N$3170,"<>retired") -> 0 | H9: =IF(G9>0,"あり","なし") -> なし
A10: Ⅰ | B10: 先天異常、周産期の異常、成長・発達の異常 | C10: 妊娠の異常 | D10: Ⅰ-1-B-③ | E10: 常位胎盤早期剝離 | F10: a | G10: =COUNTIFS(カード一覧!$G$2:$G$3170,"*医学各論 "&D10&"（*",カード一覧!$N$2:$N$3170,"<>retired") -> 0 | H10: =IF(G10>0,"あり","なし") -> なし
A11: Ⅰ | B11: 先天異常、周産期の異常、成長・発達の異常 | C11: 妊娠の異常 | D11: Ⅰ-1-B-④ | E11: 前置胎盤、癒着胎盤 | F11: a | G11: =COUNTIFS(カード一覧!$G$2:$G$3170,"*医学各論 "&D11&"（*",カード一覧!$N$2:$N$3170,"<>retired") -> 0 | H11: =IF(G11>0,"あり","なし") -> なし
A12: Ⅰ | B12: 先天異常、周産期の異常、成長・発達の異常 | C12: 妊娠の異常 | D12: Ⅰ-1-B-⑤ | E12: 多胎妊娠 | F12: b | G12: =COUNTIFS(カード一覧!$G$2:$G$3170,"*医学各論 "&D12&"（*",カード一覧!$N$2:$N$3170,"<>retired") -> 0 | H12: =IF(G12>0,"あり","なし") -> なし
A13: Ⅰ | B13: 先天異常、周産期の異常、成長・発達の異常 | C13: 妊娠の異常 | D13: Ⅰ-1-B-⑥ | E13: 前期破水 | F13: b | G13: =COUNTIFS(カード一覧!$G$2:$G$3170,"*医学各論 "&D13&"（*",カード一覧!$N$2:$N$3170,"<>retired") -> 0 | H13: =IF(G13>0,"あり","なし") -> なし
... A1483: ⅩⅢ | B1483: 生活環境因子・職業性因子による疾患 | C1483: 物理的原因・生活環境因子による障害 | D1483: ⅩⅢ-5-I-③ | E1483: 自然災害 | F1483: a | G1483: =COUNTIFS(カード一覧!$G$2:$G$3170,"*医学各論 "&D1483&"（*",カード一覧!$N$2:$N$3170,"<>retired") -> 0 | H1483: =IF(G1483>0,"あり","なし") -> なし

Sheet 説明
A1: 項目 | B1: 説明
A2: このファイルについて | B2: hm-cmed/cleanroom-facts の data/facts（カード）、data/sources（出典）、data/curriculum（出題基準）から作った一覧です。元データを変えても、このファイルは自動では更新されません（作り直す必要があります）。
A3: 件数の数え方 | B3: 「概要」と「出題基準の網羅」の件数は、「カード一覧」「出典一覧」を数える数式です。
A4: 有効と廃止 | B4: 状態（status）が retired のカードは廃止です。置き換え先の列に、統合・差し替え先のカードがあります。ID は再利用しません。
A5: 状態 | B5: draft：出典・数値の照合が未完了。verified_sources：識別子とライセンスを API で照合済み。verified_expert：専門医が監修済み（人だけが付けます）。
A6: ライセンス区分 | B6: OPEN（CC BY・CC0）、RESTRICTED（CC BY-NC・ND、出版社規約など）、GOV_JP（日本の公的資料）、GOV_US（米国連邦政府著作物）、UNKNOWN（未確認。RESTRICTED と同じ扱い）。
A7: 出題基準の網羅 | B7: カードの出題基準の欄に「医学各論 番号（」が含まれ、廃止でないカードを数えています。「作らない」とした項目は、別の章の既存カードに番号を足して受けています。
A8: 著作権 | B8: 主張文は出典の文言を写さず自作した文です。このファイルに論文やガイドラインの本文は含みません。
